Workbook

Sheet Daily Sale entry 
A1: Date 日期 | B1: Cash sale 现金销售 | C1: Misc Charges 杂项费用 | D1: Other Charges 其他费用 | E1: Credit Collection 赊账收款 | F1: b/f petty cash 上日备用金结转 | G1: c/f petty cash 今日备用金结转 | H1: Cash collection 现金收款 | I1: Cheque(unit) 支票(张数) | J1: Cheque collection 支票收款 | K1: TNG TNG收款 | L1: Advance Salary_M 预支薪水_M | M1: Advance Salary_H 预支薪水_H | O1: Date 日期 | P1: Buyer 买家 | Q1: Type 类别 | R1: Mode 方式 | S1: Amount 金额 | T1: Discount (optional) 折扣(可选) | U1: Remarks 备注 | V1: Bank-in date 存入日期 (cheque) | X1: Date 日期 | Y1: Description 说明 | Z1: Type 类别 | AA1: Debtor name 债务人 | AB1: Cheque (unit) 支票(张数) | AC1: Deposit 存入 | AD1: Withdrawal 提取 | AE1: Balance 余额
E2: =IF(A2="","",SUMPRODUCT(('Daily Sale entry '!$O$2:$O$1501=A2)*('Daily Sale entry '!$Q$2:$Q$1501="Collection 收款")*('Daily Sale entry '!$S$2:$S$1501-'Opening Balance'!$B$15*('Daily Sale entry '!$R$2:$R$1501="Cheque 支票")*('Daily Sale entry '!$S$2:$S$1501-TRUNC('Daily Sale entry '!$S$2:$S$1501))))) | AE2: =IF(X2="","",ROUND('Opening Balance'!$B$4+SUM($AC$2:AC2)-SUM($AD$2:AD2)+SUMPRODUCT(($Q$2:$Q$1501="Collection 收款")*($R$2:$R$1501="Cheque 支票")*($V$2:$V$1501<>"")*($V$2:$V$1501<=X2)*($S$2:$S$1501-'Opening Balance'!$B$15*($R$2:$R$1501="Cheque 支票")*($S$2:$S$1501-TRUNC($S$2:$S$1501))))-'Opening Balance'!$B$15*SUMPRODUCT(($Z$2:Z2="Online collection 网上收款")*($AA$2:AA2<>"")*($AC$2:AC2-TRUNC($AC$2:AC2))),2))
E3: =IF(A3="","",SUMPRODUCT(('Daily Sale entry '!$O$2:$O$1501=A3)*('Daily Sale entry '!$Q$2:$Q$1501="Collection 收款")*('Daily Sale entry '!$S$2:$S$1501-'Opening Balance'!$B$15*('Daily Sale entry '!$R$2:$R$1501="Cheque 支票")*('Daily Sale entry '!$S$2:$S$1501-TRUNC('Daily Sale entry '!$S$2:$S$1501))))) | AE3: =IF(X3="","",ROUND('Opening Balance'!$B$4+SUM($AC$2:AC3)-SUM($AD$2:AD3)+SUMPRODUCT(($Q$2:$Q$1501="Collection 收款")*($R$2:$R$1501="Cheque 支票")*($V$2:$V$1501<>"")*($V$2:$V$1501<=X3)*($S$2:$S$1501-'Opening Balance'!$B$15*($R$2:$R$1501="Cheque 支票")*($S$2:$S$1501-TRUNC($S$2:$S$1501))))-'Opening Balance'!$B$15*SUMPRODUCT(($Z$2:Z3="Online collection 网上收款")*($AA$2:AA3<>"")*($AC$2:AC3-TRUNC($AC$2:AC3))),2))
E4: =IF(A4="","",SUMPRODUCT(('Daily Sale entry '!$O$2:$O$1501=A4)*('Daily Sale entry '!$Q$2:$Q$1501="Collection 收款")*('Daily Sale entry '!$S$2:$S$1501-'Opening Balance'!$B$15*('Daily Sale entry '!$R$2:$R$1501="Cheque 支票")*('Daily Sale entry '!$S$2:$S$1501-TRUNC('Daily Sale entry '!$S$2:$S$1501))))) | AE4: =IF(X4="","",ROUND('Opening Balance'!$B$4+SUM($AC$2:AC4)-SUM($AD$2:AD4)+SUMPRODUCT(($Q$2:$Q$1501="Collection 收款")*($R$2:$R$1501="Cheque 支票")*($V$2:$V$1501<>"")*($V$2:$V$1501<=X4)*($S$2:$S$1501-'Opening Balance'!$B$15*($R$2:$R$1501="Cheque 支票")*($S$2:$S$1501-TRUNC($S$2:$S$1501))))-'Opening Balance'!$B$15*SUMPRODUCT(($Z$2:Z4="Online collection 网上收款")*($AA$2:AA4<>"")*($AC$2:AC4-TRUNC($AC$2:AC4))),2))
E5: =IF(A5="","",SUMPRODUCT(('Daily Sale entry '!$O$2:$O$1501=A5)*('Daily Sale entry '!$Q$2:$Q$1501="Collection 收款")*('Daily Sale entry '!$S$2:$S$1501-'Opening Balance'!$B$15*('Daily Sale entry '!$R$2:$R$1501="Cheque 支票")*('Daily Sale entry '!$S$2:$S$1501-TRUNC('Daily Sale entry '!$S$2:$S$1501))))) | AE5: =IF(X5="","",ROUND('Opening Balance'!$B$4+SUM($AC$2:AC5)-SUM($AD$2:AD5)+SUMPRODUCT(($Q$2:$Q$1501="Collection 收款")*($R$2:$R$1501="Cheque 支票")*($V$2:$V$1501<>"")*($V$2:$V$1501<=X5)*($S$2:$S$1501-'Opening Balance'!$B$15*($R$2:$R$1501="Cheque 支票")*($S$2:$S$1501-TRUNC($S$2:$S$1501))))-'Opening Balance'!$B$15*SUMPRODUCT(($Z$2:Z5="Online collection 网上收款")*($AA$2:AA5<>"")*($AC$2:AC5-TRUNC($AC$2:AC5))),2))
E6: =IF(A6="","",SUMPRODUCT(('Daily Sale entry '!$O$2:$O$1501=A6)*('Daily Sale entry '!$Q$2:$Q$1501="Collection 收款")*('Daily Sale entry '!$S$2:$S$1501-'Opening Balance'!$B$15*('Daily Sale entry '!$R$2:$R$1501="Cheque 支票")*('Daily Sale entry '!$S$2:$S$1501-TRUNC('Daily Sale entry '!$S$2:$S$1501))))) | AE6: =IF(X6="","",ROUND('Opening Balance'!$B$4+SUM($AC$2:AC6)-SUM($AD$2:AD6)+SUMPRODUCT(($Q$2:$Q$1501="Collection 收款")*($R$2:$R$1501="Cheque 支票")*($V$2:$V$1501<>"")*($V$2:$V$1501<=X6)*($S$2:$S$1501-'Opening Balance'!$B$15*($R$2:$R$1501="Cheque 支票")*($S$2:$S$1501-TRUNC($S$2:$S$1501))))-'Opening Balance'!$B$15*SUMPRODUCT(($Z$2:Z6="Online collection 网上收款")*($AA$2:AA6<>"")*($AC$2:AC6-TRUNC($AC$2:AC6))),2))
E7: =IF(A7="","",SUMPRODUCT(('Daily Sale entry '!$O$2:$O$1501=A7)*('Daily Sale entry '!$Q$2:$Q$1501="Collection 收款")*('Daily Sale entry '!$S$2:$S$1501-'Opening Balance'!$B$15*('Daily Sale entry '!$R$2:$R$1501="Cheque 支票")*('Daily Sale entry '!$S$2:$S$1501-TRUNC('Daily Sale entry '!$S$2:$S$1501))))) | AE7: =IF(X7="","",ROUND('Opening Balance'!$B$4+SUM($AC$2:AC7)-SUM($AD$2:AD7)+SUMPRODUCT(($Q$2:$Q$1501="Collection 收款")*($R$2:$R$1501="Cheque 支票")*($V$2:$V$1501<>"")*($V$2:$V$1501<=X7)*($S$2:$S$1501-'Opening Balance'!$B$15*($R$2:$R$1501="Cheque 支票")*($S$2:$S$1501-TRUNC($S$2:$S$1501))))-'Opening Balance'!$B$15*SUMPRODUCT(($Z$2:Z7="Online collection 网上收款")*($AA$2:AA7<>"")*($AC$2:AC7-TRUNC($AC$2:AC7))),2))
E8: =IF(A8="","",SUMPRODUCT(('Daily Sale entry '!$O$2:$O$1501=A8)*('Daily Sale entry '!$Q$2:$Q$1501="Collection 收款")*('Daily Sale entry '!$S$2:$S$1501-'Opening Balance'!$B$15*('Daily Sale entry '!$R$2:$R$1501="Cheque 支票")*('Daily Sale entry '!$S$2:$S$1501-TRUNC('Daily Sale entry '!$S$2:$S$1501))))) | AE8: =IF(X8="","",ROUND('Opening Balance'!$B$4+SUM($AC$2:AC8)-SUM($AD$2:AD8)+SUMPRODUCT(($Q$2:$Q$1501="Collection 收款")*($R$2:$R$1501="Cheque 支票")*($V$2:$V$1501<>"")*($V$2:$V$1501<=X8)*($S$2:$S$1501-'Opening Balance'!$B$15*($R$2:$R$1501="Cheque 支票")*($S$2:$S$1501-TRUNC($S$2:$S$1501))))-'Opening Balance'!$B$15*SUMPRODUCT(($Z$2:Z8="Online collection 网上收款")*($AA$2:AA8<>"")*($AC$2:AC8-TRUNC($AC$2:AC8))),2))
E9: =IF(A9="","",SUMPRODUCT(('Daily Sale entry '!$O$2:$O$1501=A9)*('Daily Sale entry '!$Q$2:$Q$1501="Collection 收款")*('Daily Sale entry '!$S$2:$S$1501-'Opening Balance'!$B$15*('Daily Sale entry '!$R$2:$R$1501="Cheque 支票")*('Daily Sale entry '!$S$2:$S$1501-TRUNC('Daily Sale entry '!$S$2:$S$1501))))) | AE9: =IF(X9="","",ROUND('Opening Balance'!$B$4+SUM($AC$2:AC9)-SUM($AD$2:AD9)+SUMPRODUCT(($Q$2:$Q$1501="Collection 收款")*($R$2:$R$1501="Cheque 支票")*($V$2:$V$1501<>"")*($V$2:$V$1501<=X9)*($S$2:$S$1501-'Opening Balance'!$B$15*($R$2:$R$1501="Cheque 支票")*($S$2:$S$1501-TRUNC($S$2:$S$1501))))-'Opening Balance'!$B$15*SUMPRODUCT(($Z$2:Z9="Online collection 网上收款")*($AA$2:AA9<>"")*($AC$2:AC9-TRUNC($AC$2:AC9))),2))
E10: =IF(A10="","",SUMPRODUCT(('Daily Sale entry '!$O$2:$O$1501=A10)*('Daily Sale entry '!$Q$2:$Q$1501="Collection 收款")*('Daily Sale entry '!$S$2:$S$1501-'Opening Balance'!$B$15*('Daily Sale entry '!$R$2:$R$1501="Cheque 支票")*('Daily Sale entry '!$S$2:$S$1501-TRUNC('Daily Sale entry '!$S$2:$S$1501))))) | AE10: =IF(X10="","",ROUND('Opening Balance'!$B$4+SUM($AC$2:AC10)-SUM($AD$2:AD10)+SUMPRODUCT(($Q$2:$Q$1501="Collection 收款")*($R$2:$R$1501="Cheque 支票")*($V$2:$V$1501<>"")*($V$2:$V$1501<=X10)*($S$2:$S$1501-'Opening Balance'!$B$15*($R$2:$R$1501="Cheque 支票")*($S$2:$S$1501-TRUNC($S$2:$S$1501))))-'Opening Balance'!$B$15*SUMPRODUCT(($Z$2:Z10="Online collection 网上收款")*($AA$2:AA10<>"")*($AC$2:AC10-TRUNC($AC$2:AC10))),2))
E11: =IF(A11="","",SUMPRODUCT(('Daily Sale entry '!$O$2:$O$1501=A11)*('Daily Sale entry '!$Q$2:$Q$1501="Collection 收款")*('Daily Sale entry '!$S$2:$S$1501-'Opening Balance'!$B$15*('Daily Sale entry '!$R$2:$R$1501="Cheque 支票")*('Daily Sale entry '!$S$2:$S$1501-TRUNC('Daily Sale entry '!$S$2:$S$1501))))) | AE11: =IF(X11="","",ROUND('Opening Balance'!$B$4+SUM($AC$2:AC11)-SUM($AD$2:AD11)+SUMPRODUCT(($Q$2:$Q$1501="Collection 收款")*($R$2:$R$1501="Cheque 支票")*($V$2:$V$1501<>"")*($V$2:$V$1501<=X11)*($S$2:$S$1501-'Opening Balance'!$B$15*($R$2:$R$1501="Cheque 支票")*($S$2:$S$1501-TRUNC($S$2:$S$1501))))-'Opening Balance'!$B$15*SUMPRODUCT(($Z$2:Z11="Online collection 网上收款")*($AA$2:AA11<>"")*($AC$2:AC11-TRUNC($AC$2:AC11))),2))
E12: =IF(A12="","",SUMPRODUCT(('Daily Sale entry '!$O$2:$O$1501=A12)*('Daily Sale entry '!$Q$2:$Q$1501="Collection 收款")*('Daily Sale entry '!$S$2:$S$1501-'Opening Balance'!$B$15*('Daily Sale entry '!$R$2:$R$1501="Cheque 支票")*('Daily Sale entry '!$S$2:$S$1501-TRUNC('Daily Sale entry '!$S$2:$S$1501))))) | AE12: =IF(X12="","",ROUND('Opening Balance'!$B$4+SUM($AC$2:AC12)-SUM($AD$2:AD12)+SUMPRODUCT(($Q$2:$Q$1501="Collection 收款")*($R$2:$R$1501="Cheque 支票")*($V$2:$V$1501<>"")*($V$2:$V$1501<=X12)*($S$2:$S$1501-'Opening Balance'!$B$15*($R$2:$R$1501="Cheque 支票")*($S$2:$S$1501-TRUNC($S$2:$S$1501))))-'Opening Balance'!$B$15*SUMPRODUCT(($Z$2:Z12="Online collection 网上收款")*($AA$2:AA12<>"")*($AC$2:AC12-TRUNC($AC$2:AC12))),2))
E13: =IF(A13="","",SUMPRODUCT(('Daily Sale entry '!$O$2:$O$1501=A13)*('Daily Sale entry '!$Q$2:$Q$1501="Collection 收款")*('Daily Sale entry '!$S$2:$S$1501-'Opening Balance'!$B$15*('Daily Sale entry '!$R$2:$R$1501="Cheque 支票")*('Daily Sale entry '!$S$2:$S$1501-TRUNC('Daily Sale entry '!$S$2:$S$1501))))) | AE13: =IF(X13="","",ROUND('Opening Balance'!$B$4+SUM($AC$2:AC13)-SUM($AD$2:AD13)+SUMPRODUCT(($Q$2:$Q$1501="Collection 收款")*($R$2:$R$1501="Cheque 支票")*($V$2:$V$1501<>"")*($V$2:$V$1501<=X13)*($S$2:$S$1501-'Opening Balance'!$B$15*($R$2:$R$1501="Cheque 支票")*($S$2:$S$1501-TRUNC($S$2:$S$1501))))-'Opening Balance'!$B$15*SUMPRODUCT(($Z$2:Z13="Online collection 网上收款")*($AA$2:AA13<>"")*($AC$2:AC13-TRUNC($AC$2:AC13))),2))
... E367: =IF(A367="","",SUMPRODUCT(('Daily Sale entry '!$O$2:$O$1501=A367)*('Daily Sale entry '!$Q$2:$Q$1501="Collection 收款")*('Daily Sale entry '!$S$2:$S$1501-'Opening Balance'!$B$15*('Daily Sale entry '!$R$2:$R$1501="Cheque 支票")*('Daily Sale entry '!$S$2:$S$1501-TRUNC('Daily Sale entry '!$S$2:$S$1501))))) | AE367: =IF(X367="","",ROUND('Opening Balance'!$B$4+SUM($AC$2:AC367)-SUM($AD$2:AD367)+SUMPRODUCT(($Q$2:$Q$1501="Collection 收款")*($R$2:$R$1501="Cheque 支票")*($V$2:$V$1501<>"")*($V$2:$V$1501<=X367)*($S$2:$S$1501-'Opening Balance'!$B$15*($R$2:$R$1501="Cheque 支票")*($S$2:$S$1501-TRUNC($S$2:$S$1501))))-'Opening Balance'!$B$15*SUMPRODUCT(($Z$2:Z367="Online collection 网上收款")*($AA$2:AA367<>"")*($AC$2:AC367-TRUNC($AC$2:AC367))),2))
AE368: =IF(X368="","",ROUND('Opening Balance'!$B$4+SUM($AC$2:AC368)-SUM($AD$2:AD368)+SUMPRODUCT(($Q$2:$Q$1501="Collection 收款")*($R$2:$R$1501="Cheque 支票")*($V$2:$V$1501<>"")*($V$2:$V$1501<=X368)*($S$2:$S$1501-'Opening Balance'!$B$15*($R$2:$R$1501="Cheque 支票")*($S$2:$S$1501-TRUNC($S$2:$S$1501))))-'Opening Balance'!$B$15*SUMPRODUCT(($Z$2:Z368="Online collection 网上收款")*($AA$2:AA368<>"")*($AC$2:AC368-TRUNC($AC$2:AC368))),2))
AE369: =IF(X369="","",ROUND('Opening Balance'!$B$4+SUM($AC$2:AC369)-SUM($AD$2:AD369)+SUMPRODUCT(($Q$2:$Q$1501="Collection 收款")*($R$2:$R$1501="Cheque 支票")*($V$2:$V$1501<>"")*($V$2:$V$1501<=X369)*($S$2:$S$1501-'Opening Balance'!$B$15*($R$2:$R$1501="Cheque 支票")*($S$2:$S$1501-TRUNC($S$2:$S$1501))))-'Opening Balance'!$B$15*SUMPRODUCT(($Z$2:Z369="Online collection 网上收款")*($AA$2:AA369<>"")*($AC$2:AC369-TRUNC($AC$2:AC369))),2))
AE370: =IF(X370="","",ROUND('Opening Balance'!$B$4+SUM($AC$2:AC370)-SUM($AD$2:AD370)+SUMPRODUCT(($Q$2:$Q$1501="Collection 收款")*($R$2:$R$1501="Cheque 支票")*($V$2:$V$1501<>"")*($V$2:$V$1501<=X370)*($S$2:$S$1501-'Opening Balance'!$B$15*($R$2:$R$1501="Cheque 支票")*($S$2:$S$1501-TRUNC($S$2:$S$1501))))-'Opening Balance'!$B$15*SUMPRODUCT(($Z$2:Z370="Online collection 网上收款")*($AA$2:AA370<>"")*($AC$2:AC370-TRUNC($AC$2:AC370))),2))
AE371: =IF(X371="","",ROUND('Opening Balance'!$B$4+SUM($AC$2:AC371)-SUM($AD$2:AD371)+SUMPRODUCT(($Q$2:$Q$1501="Collection 收款")*($R$2:$R$1501="Cheque 支票")*($V$2:$V$1501<>"")*($V$2:$V$1501<=X371)*($S$2:$S$1501-'Opening Balance'!$B$15*($R$2:$R$1501="Cheque 支票")*($S$2:$S$1501-TRUNC($S$2:$S$1501))))-'Opening Balance'!$B$15*SUMPRODUCT(($Z$2:Z371="Online collection 网上收款")*($AA$2:AA371<>"")*($AC$2:AC371-TRUNC($AC$2:AC371))),2))
AE372: =IF(X372="","",ROUND('Opening Balance'!$B$4+SUM($AC$2:AC372)-SUM($AD$2:AD372)+SUMPRODUCT(($Q$2:$Q$1501="Collection 收款")*($R$2:$R$1501="Cheque 支票")*($V$2:$V$1501<>"")*($V$2:$V$1501<=X372)*($S$2:$S$1501-'Opening Balance'!$B$15*($R$2:$R$1501="Cheque 支票")*($S$2:$S$1501-TRUNC($S$2:$S$1501))))-'Opening Balance'!$B$15*SUMPRODUCT(($Z$2:Z372="Online collection 网上收款")*($AA$2:AA372<>"")*($AC$2:AC372-TRUNC($AC$2:AC372))),2))
AE373: =IF(X373="","",ROUND('Opening Balance'!$B$4+SUM($AC$2:AC373)-SUM($AD$2:AD373)+SUMPRODUCT(($Q$2:$Q$1501="Collection 收款")*($R$2:$R$1501="Cheque 支票")*($V$2:$V$1501<>"")*($V$2:$V$1501<=X373)*($S$2:$S$1501-'Opening Balance'!$B$15*($R$2:$R$1501="Cheque 支票")*($S$2:$S$1501-TRUNC($S$2:$S$1501))))-'Opening Balance'!$B$15*SUMPRODUCT(($Z$2:Z373="Online collection 网上收款")*($AA$2:AA373<>"")*($AC$2:AC373-TRUNC($AC$2:AC373))),2))
AE374: =IF(X374="","",ROUND('Opening Balance'!$B$4+SUM($AC$2:AC374)-SUM($AD$2:AD374)+SUMPRODUCT(($Q$2:$Q$1501="Collection 收款")*($R$2:$R$1501="Cheque 支票")*($V$2:$V$1501<>"")*($V$2:$V$1501<=X374)*($S$2:$S$1501-'Opening Balance'!$B$15*($R$2:$R$1501="Cheque 支票")*($S$2:$S$1501-TRUNC($S$2:$S$1501))))-'Opening Balance'!$B$15*SUMPRODUCT(($Z$2:Z374="Online collection 网上收款")*($AA$2:AA374<>"")*($AC$2:AC374-TRUNC($AC$2:AC374))),2))
AE375: =IF(X375="","",ROUND('Opening Balance'!$B$4+SUM($AC$2:AC375)-SUM($AD$2:AD375)+SUMPRODUCT(($Q$2:$Q$1501="Collection 收款")*($R$2:$R$1501="Cheque 支票")*($V$2:$V$1501<>"")*($V$2:$V$1501<=X375)*($S$2:$S$1501-'Opening Balance'!$B$15*($R$2:$R$1501="Cheque 支票")*($S$2:$S$1501-TRUNC($S$2:$S$1501))))-'Opening Balance'!$B$15*SUMPRODUCT(($Z$2:Z375="Online collection 网上收款")*($AA$2:AA375<>"")*($AC$2:AC375-TRUNC($AC$2:AC375))),2))
AE376: =IF(X376="","",ROUND('Opening Balance'!$B$4+SUM($AC$2:AC376)-SUM($AD$2:AD376)+SUMPRODUCT(($Q$2:$Q$1501="Collection 收款")*($R$2:$R$1501="Cheque 支票")*($V$2:$V$1501<>"")*($V$2:$V$1501<=X376)*($S$2:$S$1501-'Opening Balance'!$B$15*($R$2:$R$1501="Cheque 支票")*($S$2:$S$1501-TRUNC($S$2:$S$1501))))-'Opening Balance'!$B$15*SUMPRODUCT(($Z$2:Z376="Online collection 网上收款")*($AA$2:AA376<>"")*($AC$2:AC376-TRUNC($AC$2:AC376))),2))
AE377: =IF(X377="","",ROUND('Opening Balance'!$B$4+SUM($AC$2:AC377)-SUM($AD$2:AD377)+SUMPRODUCT(($Q$2:$Q$1501="Collection 收款")*($R$2:$R$1501="Cheque 支票")*($V$2:$V$1501<>"")*($V$2:$V$1501<=X377)*($S$2:$S$1501-'Opening Balance'!$B$15*($R$2:$R$1501="Cheque 支票")*($S$2:$S$1501-TRUNC($S$2:$S$1501))))-'Opening Balance'!$B$15*SUMPRODUCT(($Z$2:Z377="Online collection 网上收款")*($AA$2:AA377<>"")*($AC$2:AC377-TRUNC($AC$2:AC377))),2))
AE378: =IF(X378="","",ROUND('Opening Balance'!$B$4+SUM($AC$2:AC378)-SUM($AD$2:AD378)+SUMPRODUCT(($Q$2:$Q$1501="Collection 收款")*($R$2:$R$1501="Cheque 支票")*($V$2:$V$1501<>"")*($V$2:$V$1501<=X378)*($S$2:$S$1501-'Opening Balance'!$B$15*($R$2:$R$1501="Cheque 支票")*($S$2:$S$1501-TRUNC($S$2:$S$1501))))-'Opening Balance'!$B$15*SUMPRODUCT(($Z$2:Z378="Online collection 网上收款")*($AA$2:AA378<>"")*($AC$2:AC378-TRUNC($AC$2:AC378))),2))
AE379: =IF(X379="","",ROUND('Opening Balance'!$B$4+SUM($AC$2:AC379)-SUM($AD$2:AD379)+SUMPRODUCT(($Q$2:$Q$1501="Collection 收款")*($R$2:$R$1501="Cheque 支票")*($V$2:$V$1501<>"")*($V$2:$V$1501<=X379)*($S$2:$S$1501-'Opening Balance'!$B$15*($R$2:$R$1501="Cheque 支票")*($S$2:$S$1501-TRUNC($S$2:$S$1501))))-'Opening Balance'!$B$15*SUMPRODUCT(($Z$2:Z379="Online collection 网上收款")*($AA$2:AA379<>"")*($AC$2:AC379-TRUNC($AC$2:AC379))),2))
... AE1501: =IF(X1501="","",ROUND('Opening Balance'!$B$4+SUM($AC$2:AC1501)-SUM($AD$2:AD1501)+SUMPRODUCT(($Q$2:$Q$1501="Collection 收款")*($R$2:$R$1501="Cheque 支票")*($V$2:$V$1501<>"")*($V$2:$V$1501<=X1501)*($S$2:$S$1501-'Opening Balance'!$B$15*($R$2:$R$1501="Cheque 支票")*($S$2:$S$1501-TRUNC($S$2:$S$1501))))-'Opening Balance'!$B$15*SUMPRODUCT(($Z$2:Z1501="Online collection 网上收款")*($AA$2:AA1501<>"")*($AC$2:AC1501-TRUNC($AC$2:AC1501))),2))

Sheet Sales & Collection
A1: Date 日期 | B1: =IF('Daily Sale entry '!$A2="","",'Daily Sale entry '!$A2) | H1: After 调整后 (After) | I1: =IF($B1="","",B1)
A2: Cash Sales 现金销售 | B2: =IF($B1="","",'Daily Sale entry '!B2) | D2: c/f petty cash 今日备用金结转 | E2: =IF($B1="","",'Daily Sale entry '!G2) | H2: Cash Sales 现金销售 | I2: =IF($B1="","",IF(AND(ABS(B12)>'Opening Balance'!$B$13,B12<0),ROUND(B2-B12,2),B2)) | K2: c/f petty cash 今日备用金结转 | L2: =IF($B1="","",IF(ABS(B12)<='Opening Balance'!$B$13,ROUND(E2+B12,2),E2))
A3: Misc Charges 杂项费用 | B3: =IF($B1="","",'Daily Sale entry '!C2) | D3: cash collection 现金收款 | E3: =IF($B1="","",'Daily Sale entry '!H2) | H3: Misc Charges 杂项费用 | I3: =IF($B1="","",IF(AND(ABS(B12)>'Opening Balance'!$B$13,B12>0),ROUND(B3+B12,2),B3)) | K3: cash collection 现金收款 | L3: =IF($B1="","",E3)
A4: Other Charges 其他费用 | B4: =IF($B1="","",'Daily Sale entry '!D2) | D4: Cheque Collection 支票收款 | E4: =IF($B1="","",'Daily Sale entry '!J2) | H4: Other Charges 其他费用 | I4: =IF($B1="","",B4) | K4: Cheque Collection 支票收款 | L4: =IF($B1="","",E4)
A5: Amount 金额 (Cash Sales - Misc - Other) | B5: =IF($B1="","",ROUND(B2-B3-B4,2)) | D5: TNG collection TNG收款 | E5: =IF($B1="","",'Daily Sale entry '!K2) | H5: Amount 金额 (Cash Sales - Misc - Other) | I5: =IF($B1="","",ROUND(I2-I3-I4,2)) | K5: TNG collection TNG收款 | L5: =IF($B1="","",E5)
A6: Credit Collection 赊账收款 | B6: =IF($B1="","",'Daily Sale entry '!E2) | D6: Advance Salary_M 预支薪水_M | E6: =IF($B1="","",'Daily Sale entry '!L2) | H6: Credit Collection 赊账收款 | I6: =IF($B1="","",B6) | K6: Advance Salary_M 预支薪水_M | L6: =IF($B1="","",E6)
A7: Amount 2 金额2 (Amount + Credit Collection) | B7: =IF($B1="","",ROUND(B5+B6,2)) | D7: Advance Salary_H 预支薪水_H | E7: =IF($B1="","",'Daily Sale entry '!M2) | H7: Amount 2 金额2 (Amount + Credit Collection) | I7: =IF($B1="","",ROUND(I5+I6,2)) | K7: Advance Salary_H 预支薪水_H | L7: =IF($B1="","",E7)
A9: b/f petty cash 上日备用金结转 | B9: =IF($B1="","",'Daily Sale entry '!F2) | H9: b/f petty cash 上日备用金结转 | I9: =IF($B1="","",B9)
A10: Total (A) 总计 (A) | B10: =IF($B1="","",ROUND(B7+B9,2)) | D10: Total(B) 总计 (B) | E10: =IF($B1="","",ROUND(E2+E3+E4+E5+E6+E7,2)) | H10: Total© 总计 (C) | I10: =IF($B1="","",ROUND(I7+I9,2)) | K10: Total(D) 总计 (D) | L10: =IF($B1="","",ROUND(L2+L3+L4+L5+L6+L7,2))
A11: Total = Amount 2 + b/f petty cash (金额2 + 上日备用金) | H11: Total = Amount 2 + b/f petty cash (金额2 + 上日备用金)
A12: Different 差额 | B12: =IF($B1="","",ROUND(B10-E10,2)) | D12: =IF($B1="","",IF(ABS(B12)>'Opening Balance'!$B$16,"ALERT 警报: Different over RM"&'Opening Balance'!$B$16&" 差额超过RM"&'Opening Balance'!$B$16&" - please check 请检查",IF(B12=0,"Tied 平衡",IF(ABS(B12)<='Opening Balance'!$B$13,"Small difference 小额差额: adjusted on c/f petty cash 已调整备用金",IF(B12>0,"Short 短收: added to Misc Charges 已加入杂项费用","Over 多收: added to Cash Sales 已加入现金销售"))))) | H12: Different 差额 | I12: =IF($B1="","",ROUND(I10-L10,2))
A15: Date 日期 | B15: =IF('Daily Sale entry '!$A3="","",'Daily Sale entry '!$A3) | H15: After 调整后 (After) | I15: =IF($B15="","",B15)
A16: Cash Sales 现金销售 | B16: =IF($B15="","",'Daily Sale entry '!B3) | D16: c/f petty cash 今日备用金结转 | E16: =IF($B15="","",'Daily Sale entry '!G3) | H16: Cash Sales 现金销售 | I16: =IF($B15="","",IF(AND(ABS(B26)>'Opening Balance'!$B$13,B26<0),ROUND(B16-B26,2),B16)) | K16: c/f petty cash 今日备用金结转 | L16: =IF($B15="","",IF(ABS(B26)<='Opening Balance'!$B$13,ROUND(E16+B26,2),E16))
A17: Misc Charges 杂项费用 | B17: =IF($B15="","",'Daily Sale entry '!C3) | D17: cash collection 现金收款 | E17: =IF($B15="","",'Daily Sale entry '!H3) | H17: Misc Charges 杂项费用 | I17: =IF($B15="","",IF(AND(ABS(B26)>'Opening Balance'!$B$13,B26>0),ROUND(B17+B26,2),B17)) | K17: cash collection 现金收款 | L17: =IF($B15="","",E17)
A18: Other Charges 其他费用 | B18: =IF($B15="","",'Daily Sale entry '!D3) | D18: Cheque Collection 支票收款 | E18: =IF($B15="","",'Daily Sale entry '!J3) | H18: Other Charges 其他费用 | I18: =IF($B15="","",B18) | K18: Cheque Collection 支票收款 | L18: =IF($B15="","",E18)
A19: Amount 金额 (Cash Sales - Misc - Other) | B19: =IF($B15="","",ROUND(B16-B17-B18,2)) | D19: TNG collection TNG收款 | E19: =IF($B15="","",'Daily Sale entry '!K3) | H19: Amount 金额 (Cash Sales - Misc - Other) | I19: =IF($B15="","",ROUND(I16-I17-I18,2)) | K19: TNG collection TNG收款 | L19: =IF($B15="","",E19)
A20: Credit Collection 赊账收款 | B20: =IF($B15="","",'Daily Sale entry '!E3) | D20: Advance Salary_M 预支薪水_M | E20: =IF($B15="","",'Daily Sale entry '!L3) | H20: Credit Collection 赊账收款 | I20: =IF($B15="","",B20) | K20: Advance Salary_M 预支薪水_M | L20: =IF($B15="","",E20)
A21: Amount 2 金额2 (Amount + Credit Collection) | B21: =IF($B15="","",ROUND(B19+B20,2)) | D21: Advance Salary_H 预支薪水_H | E21: =IF($B15="","",'Daily Sale entry '!M3) | H21: Amount 2 金额2 (Amount + Credit Collection) | I21: =IF($B15="","",ROUND(I19+I20,2)) | K21: Advance Salary_H 预支薪水_H | L21: =IF($B15="","",E21)
A23: b/f petty cash 上日备用金结转 | B23: =IF($B15="","",'Daily Sale entry '!F3) | H23: b/f petty cash 上日备用金结转 | I23: =IF($B15="","",B23)
A24: Total (A) 总计 (A) | B24: =IF($B15="","",ROUND(B21+B23,2)) | D24: Total(B) 总计 (B) | E24: =IF($B15="","",ROUND(E16+E17+E18+E19+E20+E21,2)) | H24: Total© 总计 (C) | I24: =IF($B15="","",ROUND(I21+I23,2)) | K24: Total(D) 总计 (D) | L24: =IF($B15="","",ROUND(L16+L17+L18+L19+L20+L21,2))
A25: Total = Amount 2 + b/f petty cash (金额2 + 上日备用金) | H25: Total = Amount 2 + b/f petty cash (金额2 + 上日备用金)
A26: Different 差额 | B26: =IF($B15="","",ROUND(B24-E24,2)) | D26: =IF($B15="","",IF(ABS(B26)>'Opening Balance'!$B$16,"ALERT 警报: Different over RM"&'Opening Balance'!$B$16&" 差额超过RM"&'Opening Balance'!$B$16&" - please check 请检查",IF(B26=0,"Tied 平衡",IF(ABS(B26)<='Opening Balance'!$B$13,"Small difference 小额差额: adjusted on c/f petty cash 已调整备用金",IF(B26>0,"Short 短收: added to Misc Charges 已加入杂项费用","Over 多收: added to Cash Sales 已加入现金销售"))))) | H26: Different 差额 | I26: =IF($B15="","",ROUND(I24-L24,2))
A29: Date 日期 | B29: =IF('Daily Sale entry '!$A4="","",'Daily Sale entry '!$A4) | H29: After 调整后 (After) | I29: =IF($B29="","",B29)
A30: Cash Sales 现金销售 | B30: =IF($B29="","",'Daily Sale entry '!B4) | D30: c/f petty cash 今日备用金结转 | E30: =IF($B29="","",'Daily Sale entry '!G4) | H30: Cash Sales 现金销售 | I30: =IF($B29="","",IF(AND(ABS(B40)>'Opening Balance'!$B$13,B40<0),ROUND(B30-B40,2),B30)) | K30: c/f petty cash 今日备用金结转 | L30: =IF($B29="","",IF(ABS(B40)<='Opening Balance'!$B$13,ROUND(E30+B40,2),E30))
A31: Misc Charges 杂项费用 | B31: =IF($B29="","",'Daily Sale entry '!C4) | D31: cash collection 现金收款 | E31: =IF($B29="","",'Daily Sale entry '!H4) | H31: Misc Charges 杂项费用 | I31: =IF($B29="","",IF(AND(ABS(B40)>'Opening Balance'!$B$13,B40>0),ROUND(B31+B40,2),B31)) | K31: cash collection 现金收款 | L31: =IF($B29="","",E31)
A32: Other Charges 其他费用 | B32: =IF($B29="","",'Daily Sale entry '!D4) | D32: Cheque Collection 支票收款 | E32: =IF($B29="","",'Daily Sale entry '!J4) | H32: Other Charges 其他费用 | I32: =IF($B29="","",B32) | K32: Cheque Collection 支票收款 | L32: =IF($B29="","",E32)
A33: Amount 金额 (Cash Sales - Misc - Other) | B33: =IF($B29="","",ROUND(B30-B31-B32,2)) | D33: TNG collection TNG收款 | E33: =IF($B29="","",'Daily Sale entry '!K4) | H33: Amount 金额 (Cash Sales - Misc - Other) | I33: =IF($B29="","",ROUND(I30-I31-I32,2)) | K33: TNG collection TNG收款 | L33: =IF($B29="","",E33)
A34: Credit Collection 赊账收款 | B34: =IF($B29="","",'Daily Sale entry '!E4) | D34: Advance Salary_M 预支薪水_M | E34: =IF($B29="","",'Daily Sale entry '!L4) | H34: Credit Collection 赊账收款 | I34: =IF($B29="","",B34) | K34: Advance Salary_M 预支薪水_M | L34: =IF($B29="","",E34)
A35: Amount 2 金额2 (Amount + Credit Collection) | B35: =IF($B29="","",ROUND(B33+B34,2)) | D35: Advance Salary_H 预支薪水_H | E35: =IF($B29="","",'Daily Sale entry '!M4) | H35: Amount 2 金额2 (Amount + Credit Collection) | I35: =IF($B29="","",ROUND(I33+I34,2)) | K35: Advance Salary_H 预支薪水_H | L35: =IF($B29="","",E35)
A37: b/f petty cash 上日备用金结转 | B37: =IF($B29="","",'Daily Sale entry '!F4) | H37: b/f petty cash 上日备用金结转 | I37: =IF($B29="","",B37)
A38: Total (A) 总计 (A) | B38: =IF($B29="","",ROUND(B35+B37,2)) | D38: Total(B) 总计 (B) | E38: =IF($B29="","",ROUND(E30+E31+E32+E33+E34+E35,2)) | H38: Total© 总计 (C) | I38: =IF($B29="","",ROUND(I35+I37,2)) | K38: Total(D) 总计 (D) | L38: =IF($B29="","",ROUND(L30+L31+L32+L33+L34+L35,2))
A39: Total = Amount 2 + b/f petty cash (金额2 + 上日备用金) | H39: Total = Amount 2 + b/f petty cash (金额2 + 上日备用金)
A40: Different 差额 | B40: =IF($B29="","",ROUND(B38-E38,2)) | D40: =IF($B29="","",IF(ABS(B40)>'Opening Balance'!$B$16,"ALERT 警报: Different over RM"&'Opening Balance'!$B$16&" 差额超过RM"&'Opening Balance'!$B$16&" - please check 请检查",IF(B40=0,"Tied 平衡",IF(ABS(B40)<='Opening Balance'!$B$13,"Small difference 小额差额: adjusted on c/f petty cash 已调整备用金",IF(B40>0,"Short 短收: added to Misc Charges 已加入杂项费用","Over 多收: added to Cash Sales 已加入现金销售"))))) | H40: Different 差额 | I40: =IF($B29="","",ROUND(I38-L38,2))
A43: Date 日期 | B43: =IF('Daily Sale entry '!$A5="","",'Daily Sale entry '!$A5) | H43: After 调整后 (After) | I43: =IF($B43="","",B43)
A44: Cash Sales 现金销售 | B44: =IF($B43="","",'Daily Sale entry '!B5) | D44: c/f petty cash 今日备用金结转 | E44: =IF($B43="","",'Daily Sale entry '!G5) | H44: Cash Sales 现金销售 | I44: =IF($B43="","",IF(AND(ABS(B54)>'Opening Balance'!$B$13,B54<0),ROUND(B44-B54,2),B44)) | K44: c/f petty cash 今日备用金结转 | L44: =IF($B43="","",IF(ABS(B54)<='Opening Balance'!$B$13,ROUND(E44+B54,2),E44))
A45: Misc Charges 杂项费用 | B45: =IF($B43="","",'Daily Sale entry '!C5) | D45: cash collection 现金收款 | E45: =IF($B43="","",'Daily Sale entry '!H5) | H45: Misc Charges 杂项费用 | I45: =IF($B43="","",IF(AND(ABS(B54)>'Opening Balance'!$B$13,B54>0),ROUND(B45+B54,2),B45)) | K45: cash collection 现金收款 | L45: =IF($B43="","",E45)
A46: Other Charges 其他费用 | B46: =IF($B43="","",'Daily Sale entry '!D5) | D46: Cheque Collection 支票收款 | E46: =IF($B43="","",'Daily Sale entry '!J5) | H46: Other Charges 其他费用 | I46: =IF($B43="","",B46) | K46: Cheque Collection 支票收款 | L46: =IF($B43="","",E46)
A47: Amount 金额 (Cash Sales - Misc - Other) | B47: =IF($B43="","",ROUND(B44-B45-B46,2)) | D47: TNG collection TNG收款 | E47: =IF($B43="","",'Daily Sale entry '!K5) | H47: Amount 金额 (Cash Sales - Misc - Other) | I47: =IF($B43="","",ROUND(I44-I45-I46,2)) | K47: TNG collection TNG收款 | L47: =IF($B43="","",E47)
A48: Credit Collection 赊账收款 | B48: =IF($B43="","",'Daily Sale entry '!E5) | D48: Advance Salary_M 预支薪水_M | E48: =IF($B43="","",'Daily Sale entry '!L5) | H48: Credit Collection 赊账收款 | I48: =IF($B43="","",B48) | K48: Advance Salary_M 预支薪水_M | L48: =IF($B43="","",E48)
A49: Amount 2 金额2 (Amount + Credit Collection) | B49: =IF($B43="","",ROUND(B47+B48,2)) | D49: Advance Salary_H 预支薪水_H | E49: =IF($B43="","",'Daily Sale entry '!M5) | H49: Amount 2 金额2 (Amount + Credit Collection) | I49: =IF($B43="","",ROUND(I47+I48,2)) | K49: Advance Salary_H 预支薪水_H | L49: =IF($B43="","",E49)
...

Sheet Cash flow
A1: Date 日期 | B1: Bank balance 银行余额 | C1: Cheque in hand(unit) 手头支票(张) | D1: Cheque in hand(RM) 手头支票(RM) | E1: petty cash 备用金 | F1: advance salary 预支薪水 | G1: balance cash(yet reach RM 5000) 零散现金(未满RM5000) | H1: Cash in hand (RM) 手头现金(RM) | I1: Total 总计 | J1: AR & AP Balance c/f AR&AP 结余转下日 | K1: Check (should be 0) 核对(应为0) | L1: Alert 警报
A2: =IF('Daily Sale entry '!A2="","",'Daily Sale entry '!A2) | B2: =IF($A2="","",ROUND('Opening Balance'!$B$4+SUM('Daily Sale entry '!$K$2:K2)+SUMIFS('Daily Sale entry '!$AC$2:$AC$1501,'Daily Sale entry '!$X$2:$X$1501,"<="&$A2)-SUMIFS('Daily Sale entry '!$AD$2:$AD$1501,'Daily Sale entry '!$X$2:$X$1501,"<="&$A2)+SUMPRODUCT(('Daily Sale entry '!$Q$2:$Q$1501="Collection 收款")*('Daily Sale entry '!$R$2:$R$1501="Cheque 支票")*('Daily Sale entry '!$V$2:$V$1501<>"")*('Daily Sale entry '!$V$2:$V$1501<=$A2)*('Daily Sale entry '!$S$2:$S$1501-'Opening Balance'!$B$15*('Daily Sale entry '!$R$2:$R$1501="Cheque 支票")*('Daily Sale entry '!$S$2:$S$1501-TRUNC('Daily Sale entry '!$S$2:$S$1501))))-'Opening Balance'!$B$15*SUMPRODUCT(('Daily Sale entry '!$X$2:$X$1501<=$A2)*('Daily Sale entry '!$Z$2:$Z$1501="Online collection 网上收款")*('Daily Sale entry '!$AA$2:$AA$1501<>"")*('Daily Sale entry '!$AC$2:$AC$1501-TRUNC('Daily Sale entry '!$AC$2:$AC$1501))),2)) | C2: =IF($A2="","",'Opening Balance'!$B$5+SUM('Daily Sale entry '!$I$2:I2)-SUMIFS('Daily Sale entry '!$AB$2:$AB$1501,'Daily Sale entry '!$X$2:$X$1501,"<="&$A2,'Daily Sale entry '!$Z$2:$Z$1501,"Cheque deposit 支票存入")-COUNTIFS('Daily Sale entry '!$Q$2:$Q$1501,"Collection 收款",'Daily Sale entry '!$R$2:$R$1501,"Cheque 支票",'Daily Sale entry '!$V$2:$V$1501,"<="&$A2)) | D2: =IF($A2="","",ROUND('Opening Balance'!$B$6+SUM('Daily Sale entry '!$J$2:J2)-SUMIFS('Daily Sale entry '!$AC$2:$AC$1501,'Daily Sale entry '!$X$2:$X$1501,"<="&$A2,'Daily Sale entry '!$Z$2:$Z$1501,"Cheque deposit 支票存入")-SUMPRODUCT(('Daily Sale entry '!$Q$2:$Q$1501="Collection 收款")*('Daily Sale entry '!$R$2:$R$1501="Cheque 支票")*('Daily Sale entry '!$V$2:$V$1501<>"")*('Daily Sale entry '!$V$2:$V$1501<=$A2)*('Daily Sale entry '!$S$2:$S$1501-'Opening Balance'!$B$15*('Daily Sale entry '!$R$2:$R$1501="Cheque 支票")*('Daily Sale entry '!$S$2:$S$1501-TRUNC('Daily Sale entry '!$S$2:$S$1501)))),2)) | E2: =IF($A2="","",'Opening Balance'!$B$7) | F2: =IF($A2="","",ROUND(SUMIFS('Daily Sale entry '!$L$2:$L$367,'Daily Sale entry '!$A$2:$A$367,">="&DATE(YEAR($A2),MONTH($A2),1),'Daily Sale entry '!$A$2:$A$367,"<="&$A2)+SUMIFS('Daily Sale entry '!$M$2:$M$367,'Daily Sale entry '!$A$2:$A$367,">="&DATE(YEAR($A2),MONTH($A2),1),'Daily Sale entry '!$A$2:$A$367,"<="&$A2)+IF(AND(YEAR($A2)=YEAR('Daily Sale entry '!$A$2),MONTH($A2)=MONTH('Daily Sale entry '!$A$2)),'Opening Balance'!$B$8,0),2)) | G2: =IF($A2="","",MOD(ROUND('Opening Balance'!$B$9+SUMIFS('Sales & Collection'!$L$1:$L$3,'Sales & Collection'!$K$1:$K$3,"cash collection*"),2),'Opening Balance'!$B$11)) | H2: =IF($A2="","",ROUND('Opening Balance'!$B$10+'Opening Balance'!$B$9+SUMIFS('Sales & Collection'!$L$1:$L$3,'Sales & Collection'!$K$1:$K$3,"cash collection*")-G2-SUMIFS('Daily Sale entry '!$AC$2:$AC$1501,'Daily Sale entry '!$X$2:$X$1501,"<="&$A2,'Daily Sale entry '!$Z$2:$Z$1501,"Cash deposit 现金存入"),2)) | I2: =IF($A2="","",ROUND(B2+D2+E2+F2+G2+H2,2)) | J2: =IF($A2="","",'AR & AP'!K3) | K2: =IF($A2="","",ROUND(I2-J2-SUMIFS('Daily Sale entry '!$AC$2:$AC$1501,'Daily Sale entry '!$X$2:$X$1501,"<="&$A2,'Daily Sale entry '!$Z$2:$Z$1501,"Other deposit 其他存入")+SUMIFS('Daily Sale entry '!$AD$2:$AD$1501,'Daily Sale entry '!$X$2:$X$1501,"<="&$A2)+('Opening Balance'!$B$8+SUM('Daily Sale entry '!$L$2:M2)-F2),2)) | L2: =IF($A2="","",IF(ABS('Sales & Collection'!$B$12)>'Opening Balance'!$B$16,"ALERT 警报: Different "&TEXT('Sales & Collection'!$B$12,"#,##0.00")&" 差额过大",""))
A3: =IF('Daily Sale entry '!A3="","",'Daily Sale entry '!A3) | B3: =IF($A3="","",ROUND('Opening Balance'!$B$4+SUM('Daily Sale entry '!$K$2:K3)+SUMIFS('Daily Sale entry '!$AC$2:$AC$1501,'Daily Sale entry '!$X$2:$X$1501,"<="&$A3)-SUMIFS('Daily Sale entry '!$AD$2:$AD$1501,'Daily Sale entry '!$X$2:$X$1501,"<="&$A3)+SUMPRODUCT(('Daily Sale entry '!$Q$2:$Q$1501="Collection 收款")*('Daily Sale entry '!$R$2:$R$1501="Cheque 支票")*('Daily Sale entry '!$V$2:$V$1501<>"")*('Daily Sale entry '!$V$2:$V$1501<=$A3)*('Daily Sale entry '!$S$2:$S$1501-'Opening Balance'!$B$15*('Daily Sale entry '!$R$2:$R$1501="Cheque 支票")*('Daily Sale entry '!$S$2:$S$1501-TRUNC('Daily Sale entry '!$S$2:$S$1501))))-'Opening Balance'!$B$15*SUMPRODUCT(('Daily Sale entry '!$X$2:$X$1501<=$A3)*('Daily Sale entry '!$Z$2:$Z$1501="Online collection 网上收款")*('Daily Sale entry '!$AA$2:$AA$1501<>"")*('Daily Sale entry '!$AC$2:$AC$1501-TRUNC('Daily Sale entry '!$AC$2:$AC$1501))),2)) | C3: =IF($A3="","",'Opening Balance'!$B$5+SUM('Daily Sale entry '!$I$2:I3)-SUMIFS('Daily Sale entry '!$AB$2:$AB$1501,'Daily Sale entry '!$X$2:$X$1501,"<="&$A3,'Daily Sale entry '!$Z$2:$Z$1501,"Cheque deposit 支票存入")-COUNTIFS('Daily Sale entry '!$Q$2:$Q$1501,"Collection 收款",'Daily Sale entry '!$R$2:$R$1501,"Cheque 支票",'Daily Sale entry '!$V$2:$V$1501,"<="&$A3)) | D3: =IF($A3="","",ROUND('Opening Balance'!$B$6+SUM('Daily Sale entry '!$J$2:J3)-SUMIFS('Daily Sale entry '!$AC$2:$AC$1501,'Daily Sale entry '!$X$2:$X$1501,"<="&$A3,'Daily Sale entry '!$Z$2:$Z$1501,"Cheque deposit 支票存入")-SUMPRODUCT(('Daily Sale entry '!$Q$2:$Q$1501="Collection 收款")*('Daily Sale entry '!$R$2:$R$1501="Cheque 支票")*('Daily Sale entry '!$V$2:$V$1501<>"")*('Daily Sale entry '!$V$2:$V$1501<=$A3)*('Daily Sale entry '!$S$2:$S$1501-'Opening Balance'!$B$15*('Daily Sale entry '!$R$2:$R$1501="Cheque 支票")*('Daily Sale entry '!$S$2:$S$1501-TRUNC('Daily Sale entry '!$S$2:$S$1501)))),2)) | E3: =IF($A3="","",'Opening Balance'!$B$7) | F3: =IF($A3="","",ROUND(SUMIFS('Daily Sale entry '!$L$2:$L$367,'Daily Sale entry '!$A$2:$A$367,">="&DATE(YEAR($A3),MONTH($A3),1),'Daily Sale entry '!$A$2:$A$367,"<="&$A3)+SUMIFS('Daily Sale entry '!$M$2:$M$367,'Daily Sale entry '!$A$2:$A$367,">="&DATE(YEAR($A3),MONTH($A3),1),'Daily Sale entry '!$A$2:$A$367,"<="&$A3)+IF(AND(YEAR($A3)=YEAR('Daily Sale entry '!$A$2),MONTH($A3)=MONTH('Daily Sale entry '!$A$2)),'Opening Balance'!$B$8,0),2)) | G3: =IF($A3="","",MOD(ROUND('Opening Balance'!$B$9+SUMIFS('Sales & Collection'!$L$1:$L$17,'Sales & Collection'!$K$1:$K$17,"cash collection*"),2),'Opening Balance'!$B$11)) | H3: =IF($A3="","",ROUND('Opening Balance'!$B$10+'Opening Balance'!$B$9+SUMIFS('Sales & Collection'!$L$1:$L$17,'Sales & Collection'!$K$1:$K$17,"cash collection*")-G3-SUMIFS('Daily Sale entry '!$AC$2:$AC$1501,'Daily Sale entry '!$X$2:$X$1501,"<="&$A3,'Daily Sale entry '!$Z$2:$Z$1501,"Cash deposit 现金存入"),2)) | I3: =IF($A3="","",ROUND(B3+D3+E3+F3+G3+H3,2)) | J3: =IF($A3="","",'AR & AP'!K4) | K3: =IF($A3="","",ROUND(I3-J3-SUMIFS('Daily Sale entry '!$AC$2:$AC$1501,'Daily Sale entry '!$X$2:$X$1501,"<="&$A3,'Daily Sale entry '!$Z$2:$Z$1501,"Other deposit 其他存入")+SUMIFS('Daily Sale entry '!$AD$2:$AD$1501,'Daily Sale entry '!$X$2:$X$1501,"<="&$A3)+('Opening Balance'!$B$8+SUM('Daily Sale entry '!$L$2:M3)-F3),2)) | L3: =IF($A3="","",IF(ABS('Sales & Collection'!$B$26)>'Opening Balance'!$B$16,"ALERT 警报: Different "&TEXT('Sales & Collection'!$B$26,"#,##0.00")&" 差额过大",""))
A4: =IF('Daily Sale entry '!A4="","",'Daily Sale entry '!A4) | B4: =IF($A4="","",ROUND('Opening Balance'!$B$4+SUM('Daily Sale entry '!$K$2:K4)+SUMIFS('Daily Sale entry '!$AC$2:$AC$1501,'Daily Sale entry '!$X$2:$X$1501,"<="&$A4)-SUMIFS('Daily Sale entry '!$AD$2:$AD$1501,'Daily Sale entry '!$X$2:$X$1501,"<="&$A4)+SUMPRODUCT(('Daily Sale entry '!$Q$2:$Q$1501="Collection 收款")*('Daily Sale entry '!$R$2:$R$1501="Cheque 支票")*('Daily Sale entry '!$V$2:$V$1501<>"")*('Daily Sale entry '!$V$2:$V$1501<=$A4)*('Daily Sale entry '!$S$2:$S$1501-'Opening Balance'!$B$15*('Daily Sale entry '!$R$2:$R$1501="Cheque 支票")*('Daily Sale entry '!$S$2:$S$1501-TRUNC('Daily Sale entry '!$S$2:$S$1501))))-'Opening Balance'!$B$15*SUMPRODUCT(('Daily Sale entry '!$X$2:$X$1501<=$A4)*('Daily Sale entry '!$Z$2:$Z$1501="Online collection 网上收款")*('Daily Sale entry '!$AA$2:$AA$1501<>"")*('Daily Sale entry '!$AC$2:$AC$1501-TRUNC('Daily Sale entry '!$AC$2:$AC$1501))),2)) | C4: =IF($A4="","",'Opening Balance'!$B$5+SUM('Daily Sale entry '!$I$2:I4)-SUMIFS('Daily Sale entry '!$AB$2:$AB$1501,'Daily Sale entry '!$X$2:$X$1501,"<="&$A4,'Daily Sale entry '!$Z$2:$Z$1501,"Cheque deposit 支票存入")-COUNTIFS('Daily Sale entry '!$Q$2:$Q$1501,"Collection 收款",'Daily Sale entry '!$R$2:$R$1501,"Cheque 支票",'Daily Sale entry '!$V$2:$V$1501,"<="&$A4)) | D4: =IF($A4="","",ROUND('Opening Balance'!$B$6+SUM('Daily Sale entry '!$J$2:J4)-SUMIFS('Daily Sale entry '!$AC$2:$AC$1501,'Daily Sale entry '!$X$2:$X$1501,"<="&$A4,'Daily Sale entry '!$Z$2:$Z$1501,"Cheque deposit 支票存入")-SUMPRODUCT(('Daily Sale entry '!$Q$2:$Q$1501="Collection 收款")*('Daily Sale entry '!$R$2:$R$1501="Cheque 支票")*('Daily Sale entry '!$V$2:$V$1501<>"")*('Daily Sale entry '!$V$2:$V$1501<=$A4)*('Daily Sale entry '!$S$2:$S$1501-'Opening Balance'!$B$15*('Daily Sale entry '!$R$2:$R$1501="Cheque 支票")*('Daily Sale entry '!$S$2:$S$1501-TRUNC('Daily Sale entry '!$S$2:$S$1501)))),2)) | E4: =IF($A4="","",'Opening Balance'!$B$7) | F4: =IF($A4="","",ROUND(SUMIFS('Daily Sale entry '!$L$2:$L$367,'Daily Sale entry '!$A$2:$A$367,">="&DATE(YEAR($A4),MONTH($A4),1),'Daily Sale entry '!$A$2:$A$367,"<="&$A4)+SUMIFS('Daily Sale entry '!$M$2:$M$367,'Daily Sale entry '!$A$2:$A$367,">="&DATE(YEAR($A4),MONTH($A4),1),'Daily Sale entry '!$A$2:$A$367,"<="&$A4)+IF(AND(YEAR($A4)=YEAR('Daily Sale entry '!$A$2),MONTH($A4)=MONTH('Daily Sale entry '!$A$2)),'Opening Balance'!$B$8,0),2)) | G4: =IF($A4="","",MOD(ROUND('Opening Balance'!$B$9+SUMIFS('Sales & Collection'!$L$1:$L$31,'Sales & Collection'!$K$1:$K$31,"cash collection*"),2),'Opening Balance'!$B$11)) | H4: =IF($A4="","",ROUND('Opening Balance'!$B$10+'Opening Balance'!$B$9+SUMIFS('Sales & Collection'!$L$1:$L$31,'Sales & Collection'!$K$1:$K$31,"cash collection*")-G4-SUMIFS('Daily Sale entry '!$AC$2:$AC$1501,'Daily Sale entry '!$X$2:$X$1501,"<="&$A4,'Daily Sale entry '!$Z$2:$Z$1501,"Cash deposit 现金存入"),2)) | I4: =IF($A4="","",ROUND(B4+D4+E4+F4+G4+H4,2)) | J4: =IF($A4="","",'AR & AP'!K5) | K4: =IF($A4="","",ROUND(I4-J4-SUMIFS('Daily Sale entry '!$AC$2:$AC$1501,'Daily Sale entry '!$X$2:$X$1501,"<="&$A4,'Daily Sale entry '!$Z$2:$Z$1501,"Other deposit 其他存入")+SUMIFS('Daily Sale entry '!$AD$2:$AD$1501,'Daily Sale entry '!$X$2:$X$1501,"<="&$A4)+('Opening Balance'!$B$8+SUM('Daily Sale entry '!$L$2:M4)-F4),2)) | L4: =IF($A4="","",IF(ABS('Sales & Collection'!$B$40)>'Opening Balance'!$B$16,"ALERT 警报: Different "&TEXT('Sales & Collection'!$B$40,"#,##0.00")&" 差额过大",""))
A5: =IF('Daily Sale entry '!A5="","",'Daily Sale entry '!A5) | B5: =IF($A5="","",ROUND('Opening Balance'!$B$4+SUM('Daily Sale entry '!$K$2:K5)+SUMIFS('Daily Sale entry '!$AC$2:$AC$1501,'Daily Sale entry '!$X$2:$X$1501,"<="&$A5)-SUMIFS('Daily Sale entry '!$AD$2:$AD$1501,'Daily Sale entry '!$X$2:$X$1501,"<="&$A5)+SUMPRODUCT(('Daily Sale entry '!$Q$2:$Q$1501="Collection 收款")*('Daily Sale entry '!$R$2:$R$1501="Cheque 支票")*('Daily Sale entry '!$V$2:$V$1501<>"")*('Daily Sale entry '!$V$2:$V$1501<=$A5)*('Daily Sale entry '!$S$2:$S$1501-'Opening Balance'!$B$15*('Daily Sale entry '!$R$2:$R$1501="Cheque 支票")*('Daily Sale entry '!$S$2:$S$1501-TRUNC('Daily Sale entry '!$S$2:$S$1501))))-'Opening Balance'!$B$15*SUMPRODUCT(('Daily Sale entry '!$X$2:$X$1501<=$A5)*('Daily Sale entry '!$Z$2:$Z$1501="Online collection 网上收款")*('Daily Sale entry '!$AA$2:$AA$1501<>"")*('Daily Sale entry '!$AC$2:$AC$1501-TRUNC('Daily Sale entry '!$AC$2:$AC$1501))),2)) | C5: =IF($A5="","",'Opening Balance'!$B$5+SUM('Daily Sale entry '!$I$2:I5)-SUMIFS('Daily Sale entry '!$AB$2:$AB$1501,'Daily Sale entry '!$X$2:$X$1501,"<="&$A5,'Daily Sale entry '!$Z$2:$Z$1501,"Cheque deposit 支票存入")-COUNTIFS('Daily Sale entry '!$Q$2:$Q$1501,"Collection 收款",'Daily Sale entry '!$R$2:$R$1501,"Cheque 支票",'Daily Sale entry '!$V$2:$V$1501,"<="&$A5)) | D5: =IF($A5="","",ROUND('Opening Balance'!$B$6+SUM('Daily Sale entry '!$J$2:J5)-SUMIFS('Daily Sale entry '!$AC$2:$AC$1501,'Daily Sale entry '!$X$2:$X$1501,"<="&$A5,'Daily Sale entry '!$Z$2:$Z$1501,"Cheque deposit 支票存入")-SUMPRODUCT(('Daily Sale entry '!$Q$2:$Q$1501="Collection 收款")*('Daily Sale entry '!$R$2:$R$1501="Cheque 支票")*('Daily Sale entry '!$V$2:$V$1501<>"")*('Daily Sale entry '!$V$2:$V$1501<=$A5)*('Daily Sale entry '!$S$2:$S$1501-'Opening Balance'!$B$15*('Daily Sale entry '!$R$2:$R$1501="Cheque 支票")*('Daily Sale entry '!$S$2:$S$1501-TRUNC('Daily Sale entry '!$S$2:$S$1501)))),2)) | E5: =IF($A5="","",'Opening Balance'!$B$7) | F5: =IF($A5="","",ROUND(SUMIFS('Daily Sale entry '!$L$2:$L$367,'Daily Sale entry '!$A$2:$A$367,">="&DATE(YEAR($A5),MONTH($A5),1),'Daily Sale entry '!$A$2:$A$367,"<="&$A5)+SUMIFS('Daily Sale entry '!$M$2:$M$367,'Daily Sale entry '!$A$2:$A$367,">="&DATE(YEAR($A5),MONTH($A5),1),'Daily Sale entry '!$A$2:$A$367,"<="&$A5)+IF(AND(YEAR($A5)=YEAR('Daily Sale entry '!$A$2),MONTH($A5)=MONTH('Daily Sale entry '!$A$2)),'Opening Balance'!$B$8,0),2)) | G5: =IF($A5="","",MOD(ROUND('Opening Balance'!$B$9+SUMIFS('Sales & Collection'!$L$1:$L$45,'Sales & Collection'!$K$1:$K$45,"cash collection*"),2),'Opening Balance'!$B$11)) | H5: =IF($A5="","",ROUND('Opening Balance'!$B$10+'Opening Balance'!$B$9+SUMIFS('Sales & Collection'!$L$1:$L$45,'Sales & Collection'!$K$1:$K$45,"cash collection*")-G5-SUMIFS('Daily Sale entry '!$AC$2:$AC$1501,'Daily Sale entry '!$X$2:$X$1501,"<="&$A5,'Daily Sale entry '!$Z$2:$Z$1501,"Cash deposit 现金存入"),2)) | I5: =IF($A5="","",ROUND(B5+D5+E5+F5+G5+H5,2)) | J5: =IF($A5="","",'AR & AP'!K6) | K5: =IF($A5="","",ROUND(I5-J5-SUMIFS('Daily Sale entry '!$AC$2:$AC$1501,'Daily Sale entry '!$X$2:$X$1501,"<="&$A5,'Daily Sale entry '!$Z$2:$Z$1501,"Other deposit 其他存入")+SUMIFS('Daily Sale entry '!$AD$2:$AD$1501,'Daily Sale entry '!$X$2:$X$1501,"<="&$A5)+('Opening Balance'!$B$8+SUM('Daily Sale entry '!$L$2:M5)-F5),2)) | L5: =IF($A5="","",IF(ABS('Sales & Collection'!$B$54)>'Opening Balance'!$B$16,"ALERT 警报: Different "&TEXT('Sales & Collection'!$B$54,"#,##0.00")&" 差额过大",""))
A6: =IF('Daily Sale entry '!A6="","",'Daily Sale entry '!A6) | B6: =IF($A6="","",ROUND('Opening Balance'!$B$4+SUM('Daily Sale entry '!$K$2:K6)+SUMIFS('Daily Sale entry '!$AC$2:$AC$1501,'Daily Sale entry '!$X$2:$X$1501,"<="&$A6)-SUMIFS('Daily Sale entry '!$AD$2:$AD$1501,'Daily Sale entry '!$X$2:$X$1501,"<="&$A6)+SUMPRODUCT(('Daily Sale entry '!$Q$2:$Q$1501="Collection 收款")*('Daily Sale entry '!$R$2:$R$1501="Cheque 支票")*('Daily Sale entry '!$V$2:$V$1501<>"")*('Daily Sale entry '!$V$2:$V$1501<=$A6)*('Daily Sale entry '!$S$2:$S$1501-'Opening Balance'!$B$15*('Daily Sale entry '!$R$2:$R$1501="Cheque 支票")*('Daily Sale entry '!$S$2:$S$1501-TRUNC('Daily Sale entry '!$S$2:$S$1501))))-'Opening Balance'!$B$15*SUMPRODUCT(('Daily Sale entry '!$X$2:$X$1501<=$A6)*('Daily Sale entry '!$Z$2:$Z$1501="Online collection 网上收款")*('Daily Sale entry '!$AA$2:$AA$1501<>"")*('Daily Sale entry '!$AC$2:$AC$1501-TRUNC('Daily Sale entry '!$AC$2:$AC$1501))),2)) | C6: =IF($A6="","",'Opening Balance'!$B$5+SUM('Daily Sale entry '!$I$2:I6)-SUMIFS('Daily Sale entry '!$AB$2:$AB$1501,'Daily Sale entry '!$X$2:$X$1501,"<="&$A6,'Daily Sale entry '!$Z$2:$Z$1501,"Cheque deposit 支票存入")-COUNTIFS('Daily Sale entry '!$Q$2:$Q$1501,"Collection 收款",'Daily Sale entry '!$R$2:$R$1501,"Cheque 支票",'Daily Sale entry '!$V$2:$V$1501,"<="&$A6)) | D6: =IF($A6="","",ROUND('Opening Balance'!$B$6+SUM('Daily Sale entry '!$J$2:J6)-SUMIFS('Daily Sale entry '!$AC$2:$AC$1501,'Daily Sale entry '!$X$2:$X$1501,"<="&$A6,'Daily Sale entry '!$Z$2:$Z$1501,"Cheque deposit 支票存入")-SUMPRODUCT(('Daily Sale entry '!$Q$2:$Q$1501="Collection 收款")*('Daily Sale entry '!$R$2:$R$1501="Cheque 支票")*('Daily Sale entry '!$V$2:$V$1501<>"")*('Daily Sale entry '!$V$2:$V$1501<=$A6)*('Daily Sale entry '!$S$2:$S$1501-'Opening Balance'!$B$15*('Daily Sale entry '!$R$2:$R$1501="Cheque 支票")*('Daily Sale entry '!$S$2:$S$1501-TRUNC('Daily Sale entry '!$S$2:$S$1501)))),2)) | E6: =IF($A6="","",'Opening Balance'!$B$7) | F6: =IF($A6="","",ROUND(SUMIFS('Daily Sale entry '!$L$2:$L$367,'Daily Sale entry '!$A$2:$A$367,">="&DATE(YEAR($A6),MONTH($A6),1),'Daily Sale entry '!$A$2:$A$367,"<="&$A6)+SUMIFS('Daily Sale entry '!$M$2:$M$367,'Daily Sale entry '!$A$2:$A$367,">="&DATE(YEAR($A6),MONTH($A6),1),'Daily Sale entry '!$A$2:$A$367,"<="&$A6)+IF(AND(YEAR($A6)=YEAR('Daily Sale entry '!$A$2),MONTH($A6)=MONTH('Daily Sale entry '!$A$2)),'Opening Balance'!$B$8,0),2)) | G6: =IF($A6="","",MOD(ROUND('Opening Balance'!$B$9+SUMIFS('Sales & Collection'!$L$1:$L$59,'Sales & Collection'!$K$1:$K$59,"cash collection*"),2),'Opening Balance'!$B$11)) | H6: =IF($A6="","",ROUND('Opening Balance'!$B$10+'Opening Balance'!$B$9+SUMIFS('Sales & Collection'!$L$1:$L$59,'Sales & Collection'!$K$1:$K$59,"cash collection*")-G6-SUMIFS('Daily Sale entry '!$AC$2:$AC$1501,'Daily Sale entry '!$X$2:$X$1501,"<="&$A6,'Daily Sale entry '!$Z$2:$Z$1501,"Cash deposit 现金存入"),2)) | I6: =IF($A6="","",ROUND(B6+D6+E6+F6+G6+H6,2)) | J6: =IF($A6="","",'AR & AP'!K7) | K6: =IF($A6="","",ROUND(I6-J6-SUMIFS('Daily Sale entry '!$AC$2:$AC$1501,'Daily Sale entry '!$X$2:$X$1501,"<="&$A6,'Daily Sale entry '!$Z$2:$Z$1501,"Other deposit 其他存入")+SUMIFS('Daily Sale entry '!$AD$2:$AD$1501,'Daily Sale entry '!$X$2:$X$1501,"<="&$A6)+('Opening Balance'!$B$8+SUM('Daily Sale entry '!$L$2:M6)-F6),2)) | L6: =IF($A6="","",IF(ABS('Sales & Collection'!$B$68)>'Opening Balance'!$B$16,"ALERT 警报: Different "&TEXT('Sales & Collection'!$B$68,"#,##0.00")&" 差额过大",""))
A7: =IF('Daily Sale entry '!A7="","",'Daily Sale entry '!A7) | B7: =IF($A7="","",ROUND('Opening Balance'!$B$4+SUM('Daily Sale entry '!$K$2:K7)+SUMIFS('Daily Sale entry '!$AC$2:$AC$1501,'Daily Sale entry '!$X$2:$X$1501,"<="&$A7)-SUMIFS('Daily Sale entry '!$AD$2:$AD$1501,'Daily Sale entry '!$X$2:$X$1501,"<="&$A7)+SUMPRODUCT(('Daily Sale entry '!$Q$2:$Q$1501="Collection 收款")*('Daily Sale entry '!$R$2:$R$1501="Cheque 支票")*('Daily Sale entry '!$V$2:$V$1501<>"")*('Daily Sale entry '!$V$2:$V$1501<=$A7)*('Daily Sale entry '!$S$2:$S$1501-'Opening Balance'!$B$15*('Daily Sale entry '!$R$2:$R$1501="Cheque 支票")*('Daily Sale entry '!$S$2:$S$1501-TRUNC('Daily Sale entry '!$S$2:$S$1501))))-'Opening Balance'!$B$15*SUMPRODUCT(('Daily Sale entry '!$X$2:$X$1501<=$A7)*('Daily Sale entry '!$Z$2:$Z$1501="Online collection 网上收款")*('Daily Sale entry '!$AA$2:$AA$1501<>"")*('Daily Sale entry '!$AC$2:$AC$1501-TRUNC('Daily Sale entry '!$AC$2:$AC$1501))),2)) | C7: =IF($A7="","",'Opening Balance'!$B$5+SUM('Daily Sale entry '!$I$2:I7)-SUMIFS('Daily Sale entry '!$AB$2:$AB$1501,'Daily Sale entry '!$X$2:$X$1501,"<="&$A7,'Daily Sale entry '!$Z$2:$Z$1501,"Cheque deposit 支票存入")-COUNTIFS('Daily Sale entry '!$Q$2:$Q$1501,"Collection 收款",'Daily Sale entry '!$R$2:$R$1501,"Cheque 支票",'Daily Sale entry '!$V$2:$V$1501,"<="&$A7)) | D7: =IF($A7="","",ROUND('Opening Balance'!$B$6+SUM('Daily Sale entry '!$J$2:J7)-SUMIFS('Daily Sale entry '!$AC$2:$AC$1501,'Daily Sale entry '!$X$2:$X$1501,"<="&$A7,'Daily Sale entry '!$Z$2:$Z$1501,"Cheque deposit 支票存入")-SUMPRODUCT(('Daily Sale entry '!$Q$2:$Q$1501="Collection 收款")*('Daily Sale entry '!$R$2:$R$1501="Cheque 支票")*('Daily Sale entry '!$V$2:$V$1501<>"")*('Daily Sale entry '!$V$2:$V$1501<=$A7)*('Daily Sale entry '!$S$2:$S$1501-'Opening Balance'!$B$15*('Daily Sale entry '!$R$2:$R$1501="Cheque 支票")*('Daily Sale entry '!$S$2:$S$1501-TRUNC('Daily Sale entry '!$S$2:$S$1501)))),2)) | E7: =IF($A7="","",'Opening Balance'!$B$7) | F7: =IF($A7="","",ROUND(SUMIFS('Daily Sale entry '!$L$2:$L$367,'Daily Sale entry '!$A$2:$A$367,">="&DATE(YEAR($A7),MONTH($A7),1),'Daily Sale entry '!$A$2:$A$367,"<="&$A7)+SUMIFS('Daily Sale entry '!$M$2:$M$367,'Daily Sale entry '!$A$2:$A$367,">="&DATE(YEAR($A7),MONTH($A7),1),'Daily Sale entry '!$A$2:$A$367,"<="&$A7)+IF(AND(YEAR($A7)=YEAR('Daily Sale entry '!$A$2),MONTH($A7)=MONTH('Daily Sale entry '!$A$2)),'Opening Balance'!$B$8,0),2)) | G7: =IF($A7="","",MOD(ROUND('Opening Balance'!$B$9+SUMIFS('Sales & Collection'!$L$1:$L$73,'Sales & Collection'!$K$1:$K$73,"cash collection*"),2),'Opening Balance'!$B$11)) | H7: =IF($A7="","",ROUND('Opening Balance'!$B$10+'Opening Balance'!$B$9+SUMIFS('Sales & Collection'!$L$1:$L$73,'Sales & Collection'!$K$1:$K$73,"cash collection*")-G7-SUMIFS('Daily Sale entry '!$AC$2:$AC$1501,'Daily Sale entry '!$X$2:$X$1501,"<="&$A7,'Daily Sale entry '!$Z$2:$Z$1501,"Cash deposit 现金存入"),2)) | I7: =IF($A7="","",ROUND(B7+D7+E7+F7+G7+H7,2)) | J7: =IF($A7="","",'AR & AP'!K8) | K7: =IF($A7="","",ROUND(I7-J7-SUMIFS('Daily Sale entry '!$AC$2:$AC$1501,'Daily Sale entry '!$X$2:$X$1501,"<="&$A7,'Daily Sale entry '!$Z$2:$Z$1501,"Other deposit 其他存入")+SUMIFS('Daily Sale entry '!$AD$2:$AD$1501,'Daily Sale entry '!$X$2:$X$1501,"<="&$A7)+('Opening Balance'!$B$8+SUM('Daily Sale entry '!$L$2:M7)-F7),2)) | L7: =IF($A7="","",IF(ABS('Sales & Collection'!$B$82)>'Opening Balance'!$B$16,"ALERT 警报: Different "&TEXT('Sales & Collection'!$B$82,"#,##0.00")&" 差额过大",""))
A8: =IF('Daily Sale entry '!A8="","",'Daily Sale entry '!A8) | B8: =IF($A8="","",ROUND('Opening Balance'!$B$4+SUM('Daily Sale entry '!$K$2:K8)+SUMIFS('Daily Sale entry '!$AC$2:$AC$1501,'Daily Sale entry '!$X$2:$X$1501,"<="&$A8)-SUMIFS('Daily Sale entry '!$AD$2:$AD$1501,'Daily Sale entry '!$X$2:$X$1501,"<="&$A8)+SUMPRODUCT(('Daily Sale entry '!$Q$2:$Q$1501="Collection 收款")*('Daily Sale entry '!$R$2:$R$1501="Cheque 支票")*('Daily Sale entry '!$V$2:$V$1501<>"")*('Daily Sale entry '!$V$2:$V$1501<=$A8)*('Daily Sale entry '!$S$2:$S$1501-'Opening Balance'!$B$15*('Daily Sale entry '!$R$2:$R$1501="Cheque 支票")*('Daily Sale entry '!$S$2:$S$1501-TRUNC('Daily Sale entry '!$S$2:$S$1501))))-'Opening Balance'!$B$15*SUMPRODUCT(('Daily Sale entry '!$X$2:$X$1501<=$A8)*('Daily Sale entry '!$Z$2:$Z$1501="Online collection 网上收款")*('Daily Sale entry '!$AA$2:$AA$1501<>"")*('Daily Sale entry '!$AC$2:$AC$1501-TRUNC('Daily Sale entry '!$AC$2:$AC$1501))),2)) | C8: =IF($A8="","",'Opening Balance'!$B$5+SUM('Daily Sale entry '!$I$2:I8)-SUMIFS('Daily Sale entry '!$AB$2:$AB$1501,'Daily Sale entry '!$X$2:$X$1501,"<="&$A8,'Daily Sale entry '!$Z$2:$Z$1501,"Cheque deposit 支票存入")-COUNTIFS('Daily Sale entry '!$Q$2:$Q$1501,"Collection 收款",'Daily Sale entry '!$R$2:$R$1501,"Cheque 支票",'Daily Sale entry '!$V$2:$V$1501,"<="&$A8)) | D8: =IF($A8="","",ROUND('Opening Balance'!$B$6+SUM('Daily Sale entry '!$J$2:J8)-SUMIFS('Daily Sale entry '!$AC$2:$AC$1501,'Daily Sale entry '!$X$2:$X$1501,"<="&$A8,'Daily Sale entry '!$Z$2:$Z$1501,"Cheque deposit 支票存入")-SUMPRODUCT(('Daily Sale entry '!$Q$2:$Q$1501="Collection 收款")*('Daily Sale entry '!$R$2:$R$1501="Cheque 支票")*('Daily Sale entry '!$V$2:$V$1501<>"")*('Daily Sale entry '!$V$2:$V$1501<=$A8)*('Daily Sale entry '!$S$2:$S$1501-'Opening Balance'!$B$15*('Daily Sale entry '!$R$2:$R$1501="Cheque 支票")*('Daily Sale entry '!$S$2:$S$1501-TRUNC('Daily Sale entry '!$S$2:$S$1501)))),2)) | E8: =IF($A8="","",'Opening Balance'!$B$7) | F8: =IF($A8="","",ROUND(SUMIFS('Daily Sale entry '!$L$2:$L$367,'Daily Sale entry '!$A$2:$A$367,">="&DATE(YEAR($A8),MONTH($A8),1),'Daily Sale entry '!$A$2:$A$367,"<="&$A8)+SUMIFS('Daily Sale entry '!$M$2:$M$367,'Daily Sale entry '!$A$2:$A$367,">="&DATE(YEAR($A8),MONTH($A8),1),'Daily Sale entry '!$A$2:$A$367,"<="&$A8)+IF(AND(YEAR($A8)=YEAR('Daily Sale entry '!$A$2),MONTH($A8)=MONTH('Daily Sale entry '!$A$2)),'Opening Balance'!$B$8,0),2)) | G8: =IF($A8="","",MOD(ROUND('Opening Balance'!$B$9+SUMIFS('Sales & Collection'!$L$1:$L$87,'Sales & Collection'!$K$1:$K$87,"cash collection*"),2),'Opening Balance'!$B$11)) | H8: =IF($A8="","",ROUND('Opening Balance'!$B$10+'Opening Balance'!$B$9+SUMIFS('Sales & Collection'!$L$1:$L$87,'Sales & Collection'!$K$1:$K$87,"cash collection*")-G8-SUMIFS('Daily Sale entry '!$AC$2:$AC$1501,'Daily Sale entry '!$X$2:$X$1501,"<="&$A8,'Daily Sale entry '!$Z$2:$Z$1501,"Cash deposit 现金存入"),2)) | I8: =IF($A8="","",ROUND(B8+D8+E8+F8+G8+H8,2)) | J8: =IF($A8="","",'AR & AP'!K9) | K8: =IF($A8="","",ROUND(I8-J8-SUMIFS('Daily Sale entry '!$AC$2:$AC$1501,'Daily Sale entry '!$X$2:$X$1501,"<="&$A8,'Daily Sale entry '!$Z$2:$Z$1501,"Other deposit 其他存入")+SUMIFS('Daily Sale entry '!$AD$2:$AD$1501,'Daily Sale entry '!$X$2:$X$1501,"<="&$A8)+('Opening Balance'!$B$8+SUM('Daily Sale entry '!$L$2:M8)-F8),2)) | L8: =IF($A8="","",IF(ABS('Sales & Collection'!$B$96)>'Opening Balance'!$B$16,"ALERT 警报: Different "&TEXT('Sales & Collection'!$B$96,"#,##0.00")&" 差额过大",""))
A9: =IF('Daily Sale entry '!A9="","",'Daily Sale entry '!A9) | B9: =IF($A9="","",ROUND('Opening Balance'!$B$4+SUM('Daily Sale entry '!$K$2:K9)+SUMIFS('Daily Sale entry '!$AC$2:$AC$1501,'Daily Sale entry '!$X$2:$X$1501,"<="&$A9)-SUMIFS('Daily Sale entry '!$AD$2:$AD$1501,'Daily Sale entry '!$X$2:$X$1501,"<="&$A9)+SUMPRODUCT(('Daily Sale entry '!$Q$2:$Q$1501="Collection 收款")*('Daily Sale entry '!$R$2:$R$1501="Cheque 支票")*('Daily Sale entry '!$V$2:$V$1501<>"")*('Daily Sale entry '!$V$2:$V$1501<=$A9)*('Daily Sale entry '!$S$2:$S$1501-'Opening Balance'!$B$15*('Daily Sale entry '!$R$2:$R$1501="Cheque 支票")*('Daily Sale entry '!$S$2:$S$1501-TRUNC('Daily Sale entry '!$S$2:$S$1501))))-'Opening Balance'!$B$15*SUMPRODUCT(('Daily Sale entry '!$X$2:$X$1501<=$A9)*('Daily Sale entry '!$Z$2:$Z$1501="Online collection 网上收款")*('Daily Sale entry '!$AA$2:$AA$1501<>"")*('Daily Sale entry '!$AC$2:$AC$1501-TRUNC('Daily Sale entry '!$AC$2:$AC$1501))),2)) | C9: =IF($A9="","",'Opening Balance'!$B$5+SUM('Daily Sale entry '!$I$2:I9)-SUMIFS('Daily Sale entry '!$AB$2:$AB$1501,'Daily Sale entry '!$X$2:$X$1501,"<="&$A9,'Daily Sale entry '!$Z$2:$Z$1501,"Cheque deposit 支票存入")-COUNTIFS('Daily Sale entry '!$Q$2:$Q$1501,"Collection 收款",'Daily Sale entry '!$R$2:$R$1501,"Cheque 支票",'Daily Sale entry '!$V$2:$V$1501,"<="&$A9)) | D9: =IF($A9="","",ROUND('Opening Balance'!$B$6+SUM('Daily Sale entry '!$J$2:J9)-SUMIFS('Daily Sale entry '!$AC$2:$AC$1501,'Daily Sale entry '!$X$2:$X$1501,"<="&$A9,'Daily Sale entry '!$Z$2:$Z$1501,"Cheque deposit 支票存入")-SUMPRODUCT(('Daily Sale entry '!$Q$2:$Q$1501="Collection 收款")*('Daily Sale entry '!$R$2:$R$1501="Cheque 支票")*('Daily Sale entry '!$V$2:$V$1501<>"")*('Daily Sale entry '!$V$2:$V$1501<=$A9)*('Daily Sale entry '!$S$2:$S$1501-'Opening Balance'!$B$15*('Daily Sale entry '!$R$2:$R$1501="Cheque 支票")*('Daily Sale entry '!$S$2:$S$1501-TRUNC('Daily Sale entry '!$S$2:$S$1501)))),2)) | E9: =IF($A9="","",'Opening Balance'!$B$7) | F9: =IF($A9="","",ROUND(SUMIFS('Daily Sale entry '!$L$2:$L$367,'Daily Sale entry '!$A$2:$A$367,">="&DATE(YEAR($A9),MONTH($A9),1),'Daily Sale entry '!$A$2:$A$367,"<="&$A9)+SUMIFS('Daily Sale entry '!$M$2:$M$367,'Daily Sale entry '!$A$2:$A$367,">="&DATE(YEAR($A9),MONTH($A9),1),'Daily Sale entry '!$A$2:$A$367,"<="&$A9)+IF(AND(YEAR($A9)=YEAR('Daily Sale entry '!$A$2),MONTH($A9)=MONTH('Daily Sale entry '!$A$2)),'Opening Balance'!$B$8,0),2)) | G9: =IF($A9="","",MOD(ROUND('Opening Balance'!$B$9+SUMIFS('Sales & Collection'!$L$1:$L$101,'Sales & Collection'!$K$1:$K$101,"cash collection*"),2),'Opening Balance'!$B$11)) | H9: =IF($A9="","",ROUND('Opening Balance'!$B$10+'Opening Balance'!$B$9+SUMIFS('Sales & Collection'!$L$1:$L$101,'Sales & Collection'!$K$1:$K$101,"cash collection*")-G9-SUMIFS('Daily Sale entry '!$AC$2:$AC$1501,'Daily Sale entry '!$X$2:$X$1501,"<="&$A9,'Daily Sale entry '!$Z$2:$Z$1501,"Cash deposit 现金存入"),2)) | I9: =IF($A9="","",ROUND(B9+D9+E9+F9+G9+H9,2)) | J9: =IF($A9="","",'AR & AP'!K10) | K9: =IF($A9="","",ROUND(I9-J9-SUMIFS('Daily Sale entry '!$AC$2:$AC$1501,'Daily Sale entry '!$X$2:$X$1501,"<="&$A9,'Daily Sale entry '!$Z$2:$Z$1501,"Other deposit 其他存入")+SUMIFS('Daily Sale entry '!$AD$2:$AD$1501,'Daily Sale entry '!$X$2:$X$1501,"<="&$A9)+('Opening Balance'!$B$8+SUM('Daily Sale entry '!$L$2:M9)-F9),2)) | L9: =IF($A9="","",IF(ABS('Sales & Collection'!$B$110)>'Opening Balance'!$B$16,"ALERT 警报: Different "&TEXT('Sales & Collection'!$B$110,"#,##0.00")&" 差额过大",""))
A10: =IF('Daily Sale entry '!A10="","",'Daily Sale entry '!A10) | B10: =IF($A10="","",ROUND('Opening Balance'!$B$4+SUM('Daily Sale entry '!$K$2:K10)+SUMIFS('Daily Sale entry '!$AC$2:$AC$1501,'Daily Sale entry '!$X$2:$X$1501,"<="&$A10)-SUMIFS('Daily Sale entry '!$AD$2:$AD$1501,'Daily Sale entry '!$X$2:$X$1501,"<="&$A10)+SUMPRODUCT(('Daily Sale entry '!$Q$2:$Q$1501="Collection 收款")*('Daily Sale entry '!$R$2:$R$1501="Cheque 支票")*('Daily Sale entry '!$V$2:$V$1501<>"")*('Daily Sale entry '!$V$2:$V$1501<=$A10)*('Daily Sale entry '!$S$2:$S$1501-'Opening Balance'!$B$15*('Daily Sale entry '!$R$2:$R$1501="Cheque 支票")*('Daily Sale entry '!$S$2:$S$1501-TRUNC('Daily Sale entry '!$S$2:$S$1501))))-'Opening Balance'!$B$15*SUMPRODUCT(('Daily Sale entry '!$X$2:$X$1501<=$A10)*('Daily Sale entry '!$Z$2:$Z$1501="Online collection 网上收款")*('Daily Sale entry '!$AA$2:$AA$1501<>"")*('Daily Sale entry '!$AC$2:$AC$1501-TRUNC('Daily Sale entry '!$AC$2:$AC$1501))),2)) | C10: =IF($A10="","",'Opening Balance'!$B$5+SUM('Daily Sale entry '!$I$2:I10)-SUMIFS('Daily Sale entry '!$AB$2:$AB$1501,'Daily Sale entry '!$X$2:$X$1501,"<="&$A10,'Daily Sale entry '!$Z$2:$Z$1501,"Cheque deposit 支票存入")-COUNTIFS('Daily Sale entry '!$Q$2:$Q$1501,"Collection 收款",'Daily Sale entry '!$R$2:$R$1501,"Cheque 支票",'Daily Sale entry '!$V$2:$V$1501,"<="&$A10)) | D10: =IF($A10="","",ROUND('Opening Balance'!$B$6+SUM('Daily Sale entry '!$J$2:J10)-SUMIFS('Daily Sale entry '!$AC$2:$AC$1501,'Daily Sale entry '!$X$2:$X$1501,"<="&$A10,'Daily Sale entry '!$Z$2:$Z$1501,"Cheque deposit 支票存入")-SUMPRODUCT(('Daily Sale entry '!$Q$2:$Q$1501="Collection 收款")*('Daily Sale entry '!$R$2:$R$1501="Cheque 支票")*('Daily Sale entry '!$V$2:$V$1501<>"")*('Daily Sale entry '!$V$2:$V$1501<=$A10)*('Daily Sale entry '!$S$2:$S$1501-'Opening Balance'!$B$15*('Daily Sale entry '!$R$2:$R$1501="Cheque 支票")*('Daily Sale entry '!$S$2:$S$1501-TRUNC('Daily Sale entry '!$S$2:$S$1501)))),2)) | E10: =IF($A10="","",'Opening Balance'!$B$7) | F10: =IF($A10="","",ROUND(SUMIFS('Daily Sale entry '!$L$2:$L$367,'Daily Sale entry '!$A$2:$A$367,">="&DATE(YEAR($A10),MONTH($A10),1),'Daily Sale entry '!$A$2:$A$367,"<="&$A10)+SUMIFS('Daily Sale entry '!$M$2:$M$367,'Daily Sale entry '!$A$2:$A$367,">="&DATE(YEAR($A10),MONTH($A10),1),'Daily Sale entry '!$A$2:$A$367,"<="&$A10)+IF(AND(YEAR($A10)=YEAR('Daily Sale entry '!$A$2),MONTH($A10)=MONTH('Daily Sale entry '!$A$2)),'Opening Balance'!$B$8,0),2)) | G10: =IF($A10="","",MOD(ROUND('Opening Balance'!$B$9+SUMIFS('Sales & Collection'!$L$1:$L$115,'Sales & Collection'!$K$1:$K$115,"cash collection*"),2),'Opening Balance'!$B$11)) | H10: =IF($A10="","",ROUND('Opening Balance'!$B$10+'Opening Balance'!$B$9+SUMIFS('Sales & Collection'!$L$1:$L$115,'Sales & Collection'!$K$1:$K$115,"cash collection*")-G10-SUMIFS('Daily Sale entry '!$AC$2:$AC$1501,'Daily Sale entry '!$X$2:$X$1501,"<="&$A10,'Daily Sale entry '!$Z$2:$Z$1501,"Cash deposit 现金存入"),2)) | I10: =IF($A10="","",ROUND(B10+D10+E10+F10+G10+H10,2)) | J10: =IF($A10="","",'AR & AP'!K11) | K10: =IF($A10="","",ROUND(I10-J10-SUMIFS('Daily Sale entry '!$AC$2:$AC$1501,'Daily Sale entry '!$X$2:$X$1501,"<="&$A10,'Daily Sale entry '!$Z$2:$Z$1501,"Other deposit 其他存入")+SUMIFS('Daily Sale entry '!$AD$2:$AD$1501,'Daily Sale entry '!$X$2:$X$1501,"<="&$A10)+('Opening Balance'!$B$8+SUM('Daily Sale entry '!$L$2:M10)-F10),2)) | L10: =IF($A10="","",IF(ABS('Sales & Collection'!$B$124)>'Opening Balance'!$B$16,"ALERT 警报: Different "&TEXT('Sales & Collection'!$B$124,"#,##0.00")&" 差额过大",""))
